Workbook

Sheet SGW
A1: APD-1 (Rev. 12/05)
E3: New York State
D4: Department of Agriculture and Markets | J4: SECTION A: Worksheet
C5: Division of Agricultural Protection and Development Services | J5: Information
E6: 10B Airline Drive | J6: Page 1 | K6: of 1
E7: Albany, NY 12235 | J7: X New Worksheet
J8: Revised Worksheet
D9: SOIL GROUP WORKSHEET
A11: SECTION B. LANDOWNER NAME AND PROPERTY IDENTIFICATION
A12: Landowner | B12: Last | F12: First | K12: Middle Initial
A13: Name
A14: Mailing | B14: Street/Road No. and Name | F14: City, Town, Village | J14: State | K14: Zip Code
A15: Address
A16: Property Location | D16: Street/Road No. and Name
A18: County | D18: Town/City | J18: Village
A19: Otsego
A20: Filing Status: | B20: __ | C20: Agricultural District | D20: __Individual Commitment | G20: SECTION D: PARCEL ACREAGE SUMMARY* | K20: ACRES
A22: SECTION C: TAX MAP & ASSESSMENT ROLL INFORMATION | G22: (1) Agricultural Land | K22: =K59 -> 0
A24: SWIS Code (six digits) | G24: (2) Farm Woodland (</= 50 Acres) | K24: =IF(L24>50,50,L24) -> 0
D25: section | E25: block | F25: lot
A26: Tax Map Identifier | G26: (3) Excess Farm Woodland | K26: =IF(L24>50,L24-50,0) -> 0
A28: Roll Identifier (if different) | G28: (4) Non-Agricultural Land
N29: Overflow Soils
A30: Total Parcel Acres | D30: =K30 -> 0 | G30: TOTAL ACREAGE | K30: =SUM(K22:K28) -> 0
A31: SECTION E: SOIL MAP BREAKDOWN OF AGRICULTURAL LAND | I31: SECTION F: | N31: SOIL MAP | R31: SOIL | U31: NUMBER
A32: SOIL MAP | E32: SOIL | H32: NUMBER | I32: AGRICULTURAL LAND | N32: SYMBOL | O32: SOIL MAP UNIT NAME | R32: GROUP | S32: MUKEY | U32: ACRES
A33: SYMBOL | B33: SOIL MAP UNIT NAME | E33: GROUP | F33: MUKEY | H33: ACRES | I33: SOIL GROUP SUMMARY | O33: =IFERROR(IFERROR(VLOOKUP(S33,soils2!$A$2:$D$8514,3,FALSE),VLOOKUP(N33,soils2!$B$2:$D$8514,2,FALSE)),"") | R33: =IFERROR(VLOOKUP(N33,soils2!$B$2:$D$8514,3),"")
B34: =IFERROR(IFERROR(VLOOKUP(F34,soils2!$A$2:$D$8514,3,FALSE),VLOOKUP(A34,soils2!$B$2:$D$8514,2,FALSE)),"") | E34: =IFERROR(IFERROR(VLOOKUP(F34,soils2!$A$2:$D$8514,4,FALSE),VLOOKUP(A34,soils2!$B$2:$D$8514,3,FALSE)),"") | I34: Mineral | O34: =IFERROR(IFERROR(VLOOKUP(S34,soils2!$A$2:$D$8514,3,FALSE),VLOOKUP(N34,soils2!$B$2:$D$8514,2,FALSE)),"") | R34: =IFERROR(VLOOKUP(N34,soils2!$B$2:$D$8514,3),"")
B35: =IFERROR(IFERROR(VLOOKUP(F35,soils2!$A$2:$D$8514,3,FALSE),VLOOKUP(A35,soils2!$B$2:$D$8514,2,FALSE)),"") | E35: =IFERROR(IFERROR(VLOOKUP(F35,soils2!$A$2:$D$8514,4,FALSE),VLOOKUP(A35,soils2!$B$2:$D$8514,3,FALSE)),"") | I35: Soil Group | K35: Acres | O35: =IFERROR(IFERROR(VLOOKUP(S35,soils2!$A$2:$D$8514,3,FALSE),VLOOKUP(N35,soils2!$B$2:$D$8514,2,FALSE)),"") | R35: =IFERROR(VLOOKUP(N35,soils2!$B$2:$D$8514,3),"")
B36: =IFERROR(IFERROR(VLOOKUP(F36,soils2!$A$2:$D$8514,3,FALSE),VLOOKUP(A36,soils2!$B$2:$D$8514,2,FALSE)),"") | E36: =IFERROR(IFERROR(VLOOKUP(F36,soils2!$A$2:$D$8514,4,FALSE),VLOOKUP(A36,soils2!$B$2:$D$8514,3,FALSE)),"") | I36: 1 | J36: a | K36: =SUMIF($E$34:$E$57,"1a",$H$34:$H$57)+SUMIF($R$33:$R$600,"1a",$U$33:$U$600) -> 0 | O36: =IFERROR(IFERROR(VLOOKUP(S36,soils2!$A$2:$D$8514,3,FALSE),VLOOKUP(N36,soils2!$B$2:$D$8514,2,FALSE)),"") | R36: =IFERROR(VLOOKUP(N36,soils2!$B$2:$D$8514,3),"")
B37: =IFERROR(IFERROR(VLOOKUP(F37,soils2!$A$2:$D$8514,3,FALSE),VLOOKUP(A37,soils2!$B$2:$D$8514,2,FALSE)),"") | E37: =IFERROR(IFERROR(VLOOKUP(F37,soils2!$A$2:$D$8514,4,FALSE),VLOOKUP(A37,soils2!$B$2:$D$8514,3,FALSE)),"") | J37: b | K37: =SUMIF($E$34:$E$57,"1b",$H$34:$H$57)+SUMIF($R$33:$R$600,"1b",$U$33:$U$600) -> 0 | O37: =IFERROR(IFERROR(VLOOKUP(S37,soils2!$A$2:$D$8514,3,FALSE),VLOOKUP(N37,soils2!$B$2:$D$8514,2,FALSE)),"") | R37: =IFERROR(VLOOKUP(N37,soils2!$B$2:$D$8514,3),"")
B38: =IFERROR(IFERROR(VLOOKUP(F38,soils2!$A$2:$D$8514,3,FALSE),VLOOKUP(A38,soils2!$B$2:$D$8514,2,FALSE)),"") | E38: =IFERROR(IFERROR(VLOOKUP(F38,soils2!$A$2:$D$8514,4,FALSE),VLOOKUP(A38,soils2!$B$2:$D$8514,3,FALSE)),"") | I38: 2 | J38: a | K38: =SUMIF($E$34:$E$57,"2a",$H$34:$H$57)+SUMIF($R$33:$R$600,"2a",$U$33:$U$600) -> 0 | O38: =IFERROR(IFERROR(VLOOKUP(S38,soils2!$A$2:$D$8514,3,FALSE),VLOOKUP(N38,soils2!$B$2:$D$8514,2,FALSE)),"") | R38: =IFERROR(VLOOKUP(N38,soils2!$B$2:$D$8514,3),"")
B39: =IFERROR(IFERROR(VLOOKUP(F39,soils2!$A$2:$D$8514,3,FALSE),VLOOKUP(A39,soils2!$B$2:$D$8514,2,FALSE)),"") | E39: =IFERROR(IFERROR(VLOOKUP(F39,soils2!$A$2:$D$8514,4,FALSE),VLOOKUP(A39,soils2!$B$2:$D$8514,3,FALSE)),"") | J39: b | K39: =SUMIF($E$34:$E$57,"2b",$H$34:$H$57)+SUMIF($R$33:$R$600,"2b",$U$33:$U$600) -> 0 | O39: =IFERROR(IFERROR(VLOOKUP(S39,soils2!$A$2:$D$8514,3,FALSE),VLOOKUP(N39,soils2!$B$2:$D$8514,2,FALSE)),"") | R39: =IFERROR(VLOOKUP(N39,soils2!$B$2:$D$8514,3),"")
B40: =IFERROR(IFERROR(VLOOKUP(F40,soils2!$A$2:$D$8514,3,FALSE),VLOOKUP(A40,soils2!$B$2:$D$8514,2,FALSE)),"") | E40: =IFERROR(IFERROR(VLOOKUP(F40,soils2!$A$2:$D$8514,4,FALSE),VLOOKUP(A40,soils2!$B$2:$D$8514,3,FALSE)),"") | I40: 3 | J40: a | K40: =SUMIF($E$34:$E$57,"3a",$H$34:$H$57)+SUMIF($R$33:$R$600,"3a",$U$33:$U$600) -> 0 | O40: =IFERROR(IFERROR(VLOOKUP(S40,soils2!$A$2:$D$8514,3,FALSE),VLOOKUP(N40,soils2!$B$2:$D$8514,2,FALSE)),"") | R40: =IFERROR(VLOOKUP(N40,soils2!$B$2:$D$8514,3),"")
B41: =IFERROR(IFERROR(VLOOKUP(F41,soils2!$A$2:$D$8514,3,FALSE),VLOOKUP(A41,soils2!$B$2:$D$8514,2,FALSE)),"") | E41: =IFERROR(IFERROR(VLOOKUP(F41,soils2!$A$2:$D$8514,4,FALSE),VLOOKUP(A41,soils2!$B$2:$D$8514,3,FALSE)),"") | J41: b | K41: =SUMIF($E$34:$E$57,"3b",$H$34:$H$57)+SUMIF($R$33:$R$600,"3b",$U$33:$U$600) -> 0 | O41: =IFERROR(IFERROR(VLOOKUP(S41,soils2!$A$2:$D$8514,3,FALSE),VLOOKUP(N41,soils2!$B$2:$D$8514,2,FALSE)),"") | R41: =IFERROR(VLOOKUP(N41,soils2!$B$2:$D$8514,3),"")
B42: =IFERROR(IFERROR(VLOOKUP(F42,soils2!$A$2:$D$8514,3,FALSE),VLOOKUP(A42,soils2!$B$2:$D$8514,2,FALSE)),"") | E42: =IFERROR(IFERROR(VLOOKUP(F42,soils2!$A$2:$D$8514,4,FALSE),VLOOKUP(A42,soils2!$B$2:$D$8514,3,FALSE)),"") | I42: 4 | J42: a | K42: =SUMIF($E$34:$E$57,"4a",$H$34:$H$57)+SUMIF($R$33:$R$600,"4a",$U$33:$U$600) -> 0 | O42: =IFERROR(IFERROR(VLOOKUP(S42,soils2!$A$2:$D$8514,3,FALSE),VLOOKUP(N42,soils2!$B$2:$D$8514,2,FALSE)),"") | R42: =IFERROR(VLOOKUP(N42,soils2!$B$2:$D$8514,3),"")
B43: =IFERROR(IFERROR(VLOOKUP(F43,soils2!$A$2:$D$8514,3,FALSE),VLOOKUP(A43,soils2!$B$2:$D$8514,2,FALSE)),"") | E43: =IFERROR(IFERROR(VLOOKUP(F43,soils2!$A$2:$D$8514,4,FALSE),VLOOKUP(A43,soils2!$B$2:$D$8514,3,FALSE)),"") | J43: b | K43: =SUMIF($E$34:$E$57,"4b",$H$34:$H$57)+SUMIF($R$33:$R$600,"4b",$U$33:$U$600) -> 0 | O43: =IFERROR(IFERROR(VLOOKUP(S43,soils2!$A$2:$D$8514,3,FALSE),VLOOKUP(N43,soils2!$B$2:$D$8514,2,FALSE)),"") | R43: =IFERROR(VLOOKUP(N43,soils2!$B$2:$D$8514,3),"")
B44: =IFERROR(IFERROR(VLOOKUP(F44,soils2!$A$2:$D$8514,3,FALSE),VLOOKUP(A44,soils2!$B$2:$D$8514,2,FALSE)),"") | E44: =IFERROR(IFERROR(VLOOKUP(F44,soils2!$A$2:$D$8514,4,FALSE),VLOOKUP(A44,soils2!$B$2:$D$8514,3,FALSE)),"") | I44: 5 | J44: a | K44: =SUMIF($E$34:$E$57,"5a",$H$34:$H$57)+SUMIF($R$33:$R$600,"5a",$U$33:$U$600) -> 0 | O44: =IFERROR(IFERROR(VLOOKUP(S44,soils2!$A$2:$D$8514,3,FALSE),VLOOKUP(N44,soils2!$B$2:$D$8514,2,FALSE)),"") | R44: =IFERROR(VLOOKUP(N44,soils2!$B$2:$D$8514,3),"")
B45: =IFERROR(IFERROR(VLOOKUP(F45,soils2!$A$2:$D$8514,3,FALSE),VLOOKUP(A45,soils2!$B$2:$D$8514,2,FALSE)),"") | E45: =IFERROR(IFERROR(VLOOKUP(F45,soils2!$A$2:$D$8514,4,FALSE),VLOOKUP(A45,soils2!$B$2:$D$8514,3,FALSE)),"") | J45: b | K45: =SUMIF($E$34:$E$57,"5b",$H$34:$H$57)+SUMIF($R$33:$R$600,"5b",$U$33:$U$600) -> 0 | O45: =IFERROR(IFERROR(VLOOKUP(S45,soils2!$A$2:$D$8514,3,FALSE),VLOOKUP(N45,soils2!$B$2:$D$8514,2,FALSE)),"") | R45: =IFERROR(VLOOKUP(N45,soils2!$B$2:$D$8514,3),"")
B46: =IFERROR(IFERROR(VLOOKUP(F46,soils2!$A$2:$D$8514,3,FALSE),VLOOKUP(A46,soils2!$B$2:$D$8514,2,FALSE)),"") | E46: =IFERROR(IFERROR(VLOOKUP(F46,soils2!$A$2:$D$8514,4,FALSE),VLOOKUP(A46,soils2!$B$2:$D$8514,3,FALSE)),"") | I46: 6 | J46: a | K46: =SUMIF($E$34:$E$57,"6a",$H$34:$H$57)+SUMIF($R$33:$R$600,"6a",$U$33:$U$600) -> 0 | O46: =IFERROR(IFERROR(VLOOKUP(S46,soils2!$A$2:$D$8514,3,FALSE),VLOOKUP(N46,soils2!$B$2:$D$8514,2,FALSE)),"") | R46: =IFERROR(VLOOKUP(N46,soils2!$B$2:$D$8514,3),"")
...

Sheet soils2
A1: MUKEY | B1: Code | C1: MSG | D1: Name
A2: 293126 | B2: UvC | C2: URBAN LAND-RIVERHEAD | D2: 9
A3: 293127 | B3: UwB | C3: URBAN LAND-WOODBRIDGE | D3: 9
A4: 289512 | B4: 1 | C4: UDIFLUVENTS-FLUVAQUENT | D4: 9
A5: 289617 | B5: 496E | C5: GILPIN | D5: 8
A6: 289618 | B6: 496F | C6: GILPIN | D6: 9
A7: 289369 | B7: BeC | C7: BENSON | D7: 7
A8: 289370 | B8: BkD | C8: BENSON | D8: 8
A9: 290659 | B9: GlB | C9: GALWAY-FARMINGTON-URBA | D9: 9
A10: 290660 | B10: GlC | C10: GALWAY-FARMINGTON-URBA | D10: 9
A11: 288688 | B11: Ae | C11: ALLIS | D11: 7
A12: 288689 | B12: AnA | C12: ANGOLA | D12: 6B
A13: 288690 | B13: AnB | C13: ANGOLA | D13: 6B
A14: 288691 | B14: AnC | C14: ANGOLA | D14: 7
A15: 288692 | B15: ArC | C15: ARNOT | D15: 8
A16: 288693 | B16: AsB | C16: ARNOT-ROCK OUTCROP | D16: 8
A17: 288694 | B17: AsF | C17: ARNOT-ROCK OUTCROP | D17: 9
A18: 288695 | B18: Br | C18: BIRDSALL | D18: 7
A19: 288696 | B19: BuA | C19: BURDETT | D19: 5B
A20: 288697 | B20: BuB | C20: BURDETT | D20: 5B
A21: 288698 | B21: BuC | C21: BURDETT | D21: 7
A22: 288699 | B22: BvB | C22: BURDETT | D22: 8
A23: 288700 | B23: BxA | C23: BUSTI | D23: 6B
A24: 288701 | B24: BxB | C24: BUSTI | D24: 6B
A25: 288702 | B25: Ca | C25: CARLISLE | D25: 6B
A26: 288703 | B26: CeA | C26: CASTILE | D26: 2B
A27: 288704 | B27: CeB | C27: CASTILE | D27: 2B
A28: 288705 | B28: CgB | C28: CHAUTAUQUA | D28: 3B
A29: 288706 | B29: CgC | C29: CHAUTAUQUA | D29: 5B
A30: 288707 | B30: ChA | C30: CHENANGO | D30: 2B
A31: 288708 | B31: ChB | C31: CHENANGO | D31: 2B
A32: 288709 | B32: ChC | C32: CHENANGO | D32: 5B
A33: 288710 | B33: ChD | C33: CHENANGO | D33: 6B
A34: 288711 | B34: CkB | C34: CHENANGO | D34: 2B
... A39: 288716 | B39: CoC | C39: COLONIE | D39: 6B
A40: 288717 | B40: CoD | C40: COLONIE | D40: 7
A41: 288718 | B41: CoE | C41: COLONIE | D41: 8
A42: 288719 | B42: Cs | C42: COSAD | D42: 4B
A43: 288720 | B43: Du | C43: DUMPS | D43: 9
A44: 288721 | B44: ElA | C44: ELMRIDGE | D44: 2B
...
